2024-02-10 12:30:20,340 - ERROR - Excepting error received 1005 (no status received [internal]); then sent 1005 (no status received [internal])
Traceback (most recent call last):
  File "/home/dmytro/project/big_socket/app/routers/notification.py", line 64, in web_private_notification
    await websocket.send_json({
  File "/home/dmytro/.local/lib/python3.10/site-packages/starlette/websockets.py", line 173, in send_json
    await self.send({"type": "websocket.send", "text": text})
  File "/home/dmytro/.local/lib/python3.10/site-packages/starlette/websockets.py", line 85, in send
    await self._send(message)
  File "/home/dmytro/.local/lib/python3.10/site-packages/starlette/middleware/exceptions.py", line 65, in sender
    await send(message)
  File "/home/dmytro/.local/lib/python3.10/site-packages/uvicorn/protocols/websockets/websockets_impl.py", line 320, in asgi_send
    await self.send(data)  # type: ignore[arg-type]
  File "/home/dmytro/.local/lib/python3.10/site-packages/websockets/legacy/protocol.py", line 635, in send
    await self.ensure_open()
  File "/home/dmytro/.local/lib/python3.10/site-packages/websockets/legacy/protocol.py", line 939, in ensure_open
    raise self.connection_closed_exc()
websockets.exceptions.ConnectionClosedOK: received 1005 (no status received [internal]); then sent 1005 (no status received [internal])
